Workbook

Sheet Overview
A1: AMA Communications Standard
A2: One canonical field catalog and application-packet layout is used on every transport. Multi-byte fields are big-endian.
A4: Convention | B4: Definition
A5: Canonical format | B5: LoRa, CAN, USB, and SPI use the same field widths and packet layouts.
A6: Application packet | B6: One-byte packet ID, then the canonical payload, then one explicit end-of-frame delimiter byte (value under Framing constants below).
A7: Payload length | B7: Sum of packet fields; excludes packet ID, end-of-frame delimiter, and transport framing.
A8: CRC | B8: No application-level CRC. Each transport supplies its own integrity/framing mechanism.
A9: CAN fragmentation | B9: Canonical packets larger than eight bytes must be fragmented and reassembled by the CAN transport.
A10: Byte order | B10: All multi-byte integer and IEEE-754 fields are big-endian.
A11: Uptime | B11: Unsigned uint32 milliseconds since boot; wraps after approximately 49.7 days.
A12: Scaling | B12: Physical value = raw x scale unless the field gives a formula or offset.
A13: Field ID | B13: Zero-based integer assigned in catalog order on the Fields tab. Packets are defined as ordered lists of Field IDs on the Packet Builder tab.
A15: Protocol decision / implementation note | B15: Details
A16: Filtered acceleration | B16: Signed 24-bit, 40 micro-g/count, approximately +/-335.54 g range.
... A25: End-of-frame delimiter value | B25: 0x0A
A26: End-of-frame delimiter bytes | B26: =(LEN(B25)-2)/2 -> 1
A27: Packet ID bytes | B27: 1
A28: CAN frame data bytes | B28: 8
A29: Transport CRC bytes | B29: 0

Sheet Fields
A1: Canonical Field Definitions
A2: Each field has one transport-independent type, byte width, scaling, and C definition. Field IDs are zero-based and are what the Packet Builder tab references.
A4: Field ID | B4: Field | C4: Category | D4: Source | E4: Wire type | F4: Bytes | G4: Scale / interpretation | H4: C definition | I4: Notes
A5: 0 | B5: Witness Status | C5: Witness upkeep | D5: Witness | E5: bitfield[16] | F5: 2 | G5: Byte 0 contains status flags; byte 1 is reserved. No numeric scale. | H5: IRIS_FIELD_WITNESS_STATUS_LENGTH | I5: Current firmware sets sensor-ready flags in byte 0.
A6: 1 | B6: Witness Uptime | C6: Witness upkeep | D6: Witness | E6: uint32 | F6: 4 | G6: 1 ms/count; elapsed time since boot. | H6: IRIS_FIELD_WITNESS_UPTIME_LENGTH | I6: Normative unit is milliseconds. Current heartbeat and sensor serializers emit seconds.
A7: 2 | B7: Witness MCU Temperature | C7: Witness upkeep | D7: Witness | E7: int8 | F7: 1 | G7: 1 deg C/count; signed MCU die temperature. | H7: IRIS_FIELD_WITNESS_MCU_TEMPERATURE_LENGTH | I7: One-byte canonical MCU-temperature representation selected by user.
A8: 3 | B8: Witness Battery Voltage | C8: Witness upkeep | D8: Witness | E8: uint16 | F8: 2 | G8: 1 mV/count; battery voltage in millivolts. | H8: IRIS_FIELD_WITNESS_BATTERY_VOLTAGE_LENGTH | I8: Compressed encoding is implemented by Sensors.
A9: 4 | B9: IRIS Uptime | C9: IRIS upkeep | D9: IRIS | E9: uint32 | F9: 4 | G9: 1 ms/count; elapsed time since boot. | H9: IRIS_FIELD_IRIS_UPTIME_LENGTH
A10: 5 | B10: IRIS Status | C10: IRIS upkeep | D10: IRIS | E10: bitfield[16] | F10: 2 | G10: 16 independent flags; no numeric scale. | H10: IRIS_FIELD_IRIS_STATUS_LENGTH
A11: 6 | B11: IRIS MCU Temperature | C11: IRIS upkeep | D11: IRIS | E11: int8 | F11: 1 | G11: 1 deg C/count; signed MCU die temperature. | H11: IRIS_FIELD_IRIS_MCU_TEMPERATURE_LENGTH | I11: One-byte canonical MCU-temperature representation selected by user.
A12: 7 | B12: IRIS Battery Voltage | C12: IRIS upkeep | D12: IRIS | E12: uint16 | F12: 2 | G12: 1 mV/count; battery voltage in millivolts. | H12: IRIS_FIELD_IRIS_BATTERY_VOLTAGE_LENGTH
A13: 8 | B13: Filtered Accel X | C13: Filtered estimates | D13: Witness | E13: signed int24 | F13: 3 | G13: 40 micro-g/count; acceleration in g = raw x 0.000040; range approximately -335.54 to +335.54 g. | H13: IRIS_FIELD_FILTERED_ACCEL_X_LENGTH | I13: Three-byte canonical filtered-acceleration representation selected by user. Current firmware fills it from low-g samples until an estimator output is available.
A14: 9 | B14: Filtered Accel Y | C14: Filtered estimates | D14: Witness | E14: signed int24 | F14: 3 | G14: 40 micro-g/count; acceleration in g = raw x 0.000040; range approximately -335.54 to +335.54 g. | H14: IRIS_FIELD_FILTERED_ACCEL_Y_LENGTH | I14: Three-byte canonical filtered-acceleration representation selected by user. Current firmware fills it from low-g samples until an estimator output is available.
A15: 10 | B15: Filtered Accel Z | C15: Filtered estimates | D15: Witness | E15: signed int24 | F15: 3 | G15: 40 micro-g/count; acceleration in g = raw x 0.000040; range approximately -335.54 to +335.54 g. | H15: IRIS_FIELD_FILTERED_ACCEL_Z_LENGTH | I15: Three-byte canonical filtered-acceleration representation selected by user. Current firmware fills it from low-g samples until an estimator output is available.
A16: 11 | B16: Orientation Quaternion X | C16: Filtered estimates | D16: Witness | E16: IEEE-754 float32 | F16: 4 | G16: Unitless normalized quaternion component. | H16: IRIS_FIELD_ORIENTATION_QUAT_X_LENGTH | I16: Compressed scaling is the explicit protocol interpretation for this revision.
A17: 12 | B17: Orientation Quaternion Y | C17: Filtered estimates | D17: Witness | E17: IEEE-754 float32 | F17: 4 | G17: Unitless normalized quaternion component. | H17: IRIS_FIELD_ORIENTATION_QUAT_Y_LENGTH | I17: Compressed scaling is the explicit protocol interpretation for this revision.
A18: 13 | B18: Orientation Quaternion Z | C18: Filtered estimates | D18: Witness | E18: IEEE-754 float32 | F18: 4 | G18: Unitless normalized quaternion component. | H18: IRIS_FIELD_ORIENTATION_QUAT_Z_LENGTH | I18: Compressed scaling is the explicit protocol interpretation for this revision.
A19: 14 | B19: Orientation Quaternion W | C19: Filtered estimates | D19: Witness | E19: IEEE-754 float32 | F19: 4 | G19: Unitless normalized quaternion component. | H19: IRIS_FIELD_ORIENTATION_QUAT_W_LENGTH | I19: Compressed scaling is the explicit protocol interpretation for this revision.
A20: 15 | B20: Position X | C20: Filtered estimates | D20: Witness | E20: IEEE-754 float32 | F20: 4 | G20: Meters in the estimator local frame. | H20: IRIS_FIELD_POSITION_X_LENGTH
A21: 16 | B21: Position Y | C21: Filtered estimates | D21: Witness | E21: IEEE-754 float32 | F21: 4 | G21: Meters in the estimator local frame. | H21: IRIS_FIELD_POSITION_Y_LENGTH
A22: 17 | B22: Position Z | C22: Filtered estimates | D22: Witness | E22: IEEE-754 float32 | F22: 4 | G22: Meters in the estimator local frame. | H22: IRIS_FIELD_POSITION_Z_LENGTH
A23: 18 | B23: Velocity X | C23: Filtered estimates | D23: Witness | E23: IEEE-754 float32 | F23: 4 | G23: Meters per second in the estimator local frame. | H23: IRIS_FIELD_VELOCITY_X_LENGTH
A24: 19 | B24: Velocity Y | C24: Filtered estimates | D24: Witness | E24: IEEE-754 float32 | F24: 4 | G24: Meters per second in the estimator local frame. | H24: IRIS_FIELD_VELOCITY_Y_LENGTH
A25: 20 | B25: Velocity Z | C25: Filtered estimates | D25: Witness | E25: IEEE-754 float32 | F25: 4 | G25: Meters per second in the estimator local frame. | H25: IRIS_FIELD_VELOCITY_Z_LENGTH
A26: 21 | B26: LSM6 Low Accel X | C26: Raw sensors | D26: Witness | E26: int16 | F26: 2 | G26: 0.488 mg/count at +/-16 g. | H26: IRIS_FIELD_LSM6_LOW_ACCEL_X_LENGTH
A27: 22 | B27: LSM6 Low Accel Y | C27: Raw sensors | D27: Witness | E27: int16 | F27: 2 | G27: 0.488 mg/count at +/-16 g. | H27: IRIS_FIELD_LSM6_LOW_ACCEL_Y_LENGTH
A28: 23 | B28: LSM6 Low Accel Z | C28: Raw sensors | D28: Witness | E28: int16 | F28: 2 | G28: 0.488 mg/count at +/-16 g. | H28: IRIS_FIELD_LSM6_LOW_ACCEL_Z_LENGTH
A29: 24 | B29: LSM6 Temperature | C29: Raw sensors | D29: Witness | E29: int16 | F29: 2 | G29: Sensor raw code; deg C = 25 + raw / 256. | H29: IRIS_FIELD_LSM6_TEMPERATURE_LENGTH | I29: Best-guess resolution: selected the later one-byte workbook definition. Uncompressed form remains the native LSM6 raw code.
A30: 25 | B30: LSM6 High Accel X | C30: Raw sensors | D30: Witness | E30: int16 | F30: 2 | G30: 10.417 mg/count at +/-320 g. | H30: IRIS_FIELD_LSM6_HIGH_ACCEL_X_LENGTH
A31: 26 | B31: LSM6 High Accel Y | C31: Raw sensors | D31: Witness | E31: int16 | F31: 2 | G31: 10.417 mg/count at +/-320 g. | H31: IRIS_FIELD_LSM6_HIGH_ACCEL_Y_LENGTH
A32: 27 | B32: LSM6 High Accel Z | C32: Raw sensors | D32: Witness | E32: int16 | F32: 2 | G32: 10.417 mg/count at +/-320 g. | H32: IRIS_FIELD_LSM6_HIGH_ACCEL_Z_LENGTH
A33: 28 | B33: LSM6 Gyro X | C33: Raw sensors | D33: Witness | E33: int16 | F33: 2 | G33: 70 mdps/count at +/-2000 dps. | H33: IRIS_FIELD_LSM6_GYRO_X_LENGTH
A34: 29 | B34: LSM6 Gyro Y | C34: Raw sensors | D34: Witness | E34: int16 | F34: 2 | G34: 70 mdps/count at +/-2000 dps. | H34: IRIS_FIELD_LSM6_GYRO_Y_LENGTH
A35: 30 | B35: LSM6 Gyro Z | C35: Raw sensors | D35: Witness | E35: int16 | F35: 2 | G35: 70 mdps/count at +/-2000 dps. | H35: IRIS_FIELD_LSM6_GYRO_Z_LENGTH
A36: 31 | B36: MS5607 Pressure | C36: Raw sensors | D36: Witness | E36: uint24 | F36: 3 | G36: 1 Pa/count (equivalent to 0.01 mbar/count). | H36: IRIS_FIELD_MS5607_PRESSURE_LENGTH | I36: The driver stores compensated pressure in Pa/centi-mbar units.
A37: 32 | B37: MS5607 Temperature | C37: Raw sensors | D37: Witness | E37: int16 | F37: 2 | G37: 0.01 deg C/count. | H37: IRIS_FIELD_MS5607_TEMPERATURE_LENGTH
A38: 33 | B38: MS5607 Altitude | C38: Raw sensors | D38: Witness | E38: IEEE-754 float32 | F38: 4 | G38: Meters above the configured pressure reference. | H38: IRIS_FIELD_MS5607_ALTITUDE_LENGTH | I38: Current 0x02 serializer emits this as big-endian float32.
A39: 34 | B39: Latitude | C39: Raw sensors | D39: Witness | E39: signed int24 | F39: 3 | G39: 0.0001 degree/count; degrees = raw / 10,000. | H39: IRIS_FIELD_LATITUDE_LENGTH
A40: 35 | B40: Longitude | C40: Raw sensors | D40: Witness | E40: signed int24 | F40: 3 | G40: 0.0001 degree/count; degrees = raw / 10,000. | H40: IRIS_FIELD_LONGITUDE_LENGTH
A41: 36 | B41: GPS Time | C41: Raw sensors | D41: Witness | E41: uint32 | F41: 4 | G41: 1 second/count; Unix timestamp in UTC. | H41: IRIS_FIELD_GPS_TIME_LENGTH
...

Sheet Packet Builder
A1: Packet Builder
A2: Define a packet in one row: Packet ID, name, direction, rate, and the ordered list of Field IDs (comma-separated, in wire order; IDs are on the Fields tab). Dark-blue headers are inputs, light-blue are calculated. Application packet = packet ID + payload + end-of-frame delimiter. The Packets tab regenerates the byte layout.
A4: Packet ID | B4: Name | C4: Direction | D4: Rate | E4: Field IDs (wire order, comma-separated) | F4: Fields | G4: Payload bytes | H4: Packet ID bytes | I4: EOF bytes | J4: Application packet bytes | K4: Minimum 8-byte CAN frames | L4: Transport CRC bytes | M4: Check | N4: Notes | O4: Cumulative layout rows (helper) | P4: Field IDs, spaces removed (helper)
A5: 0x01 | B5: Sensors | C5: Witness -> peer | D5: 10 Hz nominal | E5: 0, 1, 8, 9, 10, 28, 29, 30 | F5: =IF($A5="","",IF($P5="",0,LEN($P5)-LEN(SUBSTITUTE($P5,",",""))+1)) -> 8 | G5: =IF($A5="","",SUMIFS(Packets!$G$5:$G$404,Packets!$L$5:$L$404,ROWS($A$5:$A5),Packets!$C$5:$C$404,"<="&$F5)) -> 21 | H5: =IF($A5="","",Overview!$B$27) -> 1 | I5: =IF($A5="","",Overview!$B$26) -> 1 | J5: =IF($A5="","",G5+H5+I5) -> 23 | K5: =IF($A5="","",ROUNDUP(J5/Overview!$B$28,0)) -> 3 | L5: =IF($A5="","",Overview!$B$29) -> 0 | M5: =IF(AND($A5="",$E5=""),"",IF($A5="","Enter a Packet ID",IF(COUNTIF($A$5:$A$34,$A5)>1,"Duplicate Packet ID",IF($F5=0,"No Field IDs entered",IF(SUMPRODUCT(--ISNUMBER(FIND(","&Fields!$A$5:$A$48&",",","&$P5&",")))<>$F5,"Check Field IDs: unknown, blank, or repeated",IF(COUNTIFS(Packets!$L$5:$L$404,ROWS($A$5:$A5),Packets!$D$5:$D$404,"ERR")+COUNTIFS(Packets!$L$5:$L$404,ROWS($A$5:$A5),Packets!$E$5:$E$404,"MISSING")>0,"Layout error: see Packets tab",IF($O5>ROWS(Packets!$A$5:$A$404),"Exceeds Packets tab capacity","OK"))))))) -> OK | N5: Status, uptime, filtered acceleration, and gyro. | O5: =SUM($F$5:$F5)+COUNTA($A$5:$A5) -> 9 | P5: =SUBSTITUTE($E5," ","") -> 0,1,8,9,10,28,29,30
A6: 0x02 | B6: State | C6: Witness -> peer | D6: 1 Hz firmware | E6: 0, 1, 11, 12, 13, 14, 15, 16, 17, 18, 19, 20, 34, 35, 37, 33, 3 | F6: =IF($A6="","",IF($P6="",0,LEN($P6)-LEN(SUBSTITUTE($P6,",",""))+1)) -> 17 | G6: =IF($A6="","",SUMIFS(Packets!$G$5:$G$404,Packets!$L$5:$L$404,ROWS($A$5:$A6),Packets!$C$5:$C$404,"<="&$F6)) -> 62 | H6: =IF($A6="","",Overview!$B$27) -> 1 | I6: =IF($A6="","",Overview!$B$26) -> 1 | J6: =IF($A6="","",G6+H6+I6) -> 64 | K6: =IF($A6="","",ROUNDUP(J6/Overview!$B$28,0)) -> 8 | L6: =IF($A6="","",Overview!$B$29) -> 0 | M6: =IF(AND($A6="",$E6=""),"",IF($A6="","Enter a Packet ID",IF(COUNTIF($A$5:$A$34,$A6)>1,"Duplicate Packet ID",IF($F6=0,"No Field IDs entered",IF(SUMPRODUCT(--ISNUMBER(FIND(","&Fields!$A$5:$A$48&",",","&$P6&",")))<>$F6,"Check Field IDs: unknown, blank, or repeated",IF(COUNTIFS(Packets!$L$5:$L$404,ROWS($A$5:$A6),Packets!$D$5:$D$404,"ERR")+COUNTIFS(Packets!$L$5:$L$404,ROWS($A$5:$A6),Packets!$E$5:$E$404,"MISSING")>0,"Layout error: see Packets tab",IF($O6>ROWS(Packets!$A$5:$A$404),"Exceeds Packets tab capacity","OK"))))))) -> OK | N6: Estimated state, navigation, barometric altitude, and FC battery. | O6: =SUM($F$5:$F6)+COUNTA($A$5:$A6) -> 27 | P6: =SUBSTITUTE($E6," ","") -> 0,1,11,12,13,14,15,16,17,18,19,20,34,35,37,33,3
A7: 0x03 | B7: Camera | C7: IRIS/Witness -> peer | D7: 1 Hz nominal | E7: 0, 1, 5, 4, 38, 39, 40, 7 | F7: =IF($A7="","",IF($P7="",0,LEN($P7)-LEN(SUBSTITUTE($P7,",",""))+1)) -> 8 | G7: =IF($A7="","",SUMIFS(Packets!$G$5:$G$404,Packets!$L$5:$L$404,ROWS($A$5:$A7),Packets!$C$5:$C$404,"<="&$F7)) -> 17 | H7: =IF($A7="","",Overview!$B$27) -> 1 | I7: =IF($A7="","",Overview!$B$26) -> 1 | J7: =IF($A7="","",G7+H7+I7) -> 19 | K7: =IF($A7="","",ROUNDUP(J7/Overview!$B$28,0)) -> 3 | L7: =IF($A7="","",Overview!$B$29) -> 0 | M7: =IF(AND($A7="",$E7=""),"",IF($A7="","Enter a Packet ID",IF(COUNTIF($A$5:$A$34,$A7)>1,"Duplicate Packet ID",IF($F7=0,"No Field IDs entered",IF(SUMPRODUCT(--ISNUMBER(FIND(","&Fields!$A$5:$A$48&",",","&$P7&",")))<>$F7,"Check Field IDs: unknown, blank, or repeated",IF(COUNTIFS(Packets!$L$5:$L$404,ROWS($A$5:$A7),Packets!$D$5:$D$404,"ERR")+COUNTIFS(Packets!$L$5:$L$404,ROWS($A$5:$A7),Packets!$E$5:$E$404,"MISSING")>0,"Layout error: see Packets tab",IF($O7>ROWS(Packets!$A$5:$A$404),"Exceeds Packets tab capacity","OK"))))))) -> OK | N7: Witness and IRIS status, current sensing, and IRIS battery. | O7: =SUM($F$5:$F7)+COUNTA($A$5:$A7) -> 36 | P7: =SUBSTITUTE($E7," ","") -> 0,1,5,4,38,39,40,7
A8: 0x05 | B8: Command | C8: Controller -> board | D8: On demand | E8: 42, 43, 41 | F8: =IF($A8="","",IF($P8="",0,LEN($P8)-LEN(SUBSTITUTE($P8,",",""))+1)) -> 3 | G8: =IF($A8="","",SUMIFS(Packets!$G$5:$G$404,Packets!$L$5:$L$404,ROWS($A$5:$A8),Packets!$C$5:$C$404,"<="&$F8)) -> 8 | H8: =IF($A8="","",Overview!$B$27) -> 1 | I8: =IF($A8="","",Overview!$B$26) -> 1 | J8: =IF($A8="","",G8+H8+I8) -> 10 | K8: =IF($A8="","",ROUNDUP(J8/Overview!$B$28,0)) -> 2 | L8: =IF($A8="","",Overview!$B$29) -> 0 | M8: =IF(AND($A8="",$E8=""),"",IF($A8="","Enter a Packet ID",IF(COUNTIF($A$5:$A$34,$A8)>1,"Duplicate Packet ID",IF($F8=0,"No Field IDs entered",IF(SUMPRODUCT(--ISNUMBER(FIND(","&Fields!$A$5:$A$48&",",","&$P8&",")))<>$F8,"Check Field IDs: unknown, blank, or repeated",IF(COUNTIFS(Packets!$L$5:$L$404,ROWS($A$5:$A8),Packets!$D$5:$D$404,"ERR")+COUNTIFS(Packets!$L$5:$L$404,ROWS($A$5:$A8),Packets!$E$5:$E$404,"MISSING")>0,"Layout error: see Packets tab",IF($O8>ROWS(Packets!$A$5:$A$404),"Exceeds Packets tab capacity","OK"))))))) -> OK | N8: Command packet. | O8: =SUM($F$5:$F8)+COUNTA($A$5:$A8) -> 40 | P8: =SUBSTITUTE($E8," ","") -> 42,43,41
A9: 0xFF | B9: Heartbeat | C9: Board -> peer | D9: 1 Hz | E9: 42, 43 | F9: =IF($A9="","",IF($P9="",0,LEN($P9)-LEN(SUBSTITUTE($P9,",",""))+1)) -> 2 | G9: =IF($A9="","",SUMIFS(Packets!$G$5:$G$404,Packets!$L$5:$L$404,ROWS($A$5:$A9),Packets!$C$5:$C$404,"<="&$F9)) -> 6 | H9: =IF($A9="","",Overview!$B$27) -> 1 | I9: =IF($A9="","",Overview!$B$26) -> 1 | J9: =IF($A9="","",G9+H9+I9) -> 8 | K9: =IF($A9="","",ROUNDUP(J9/Overview!$B$28,0)) -> 1 | L9: =IF($A9="","",Overview!$B$29) -> 0 | M9: =IF(AND($A9="",$E9=""),"",IF($A9="","Enter a Packet ID",IF(COUNTIF($A$5:$A$34,$A9)>1,"Duplicate Packet ID",IF($F9=0,"No Field IDs entered",IF(SUMPRODUCT(--ISNUMBER(FIND(","&Fields!$A$5:$A$48&",",","&$P9&",")))<>$F9,"Check Field IDs: unknown, blank, or repeated",IF(COUNTIFS(Packets!$L$5:$L$404,ROWS($A$5:$A9),Packets!$D$5:$D$404,"ERR")+COUNTIFS(Packets!$L$5:$L$404,ROWS($A$5:$A9),Packets!$E$5:$E$404,"MISSING")>0,"Layout error: see Packets tab",IF($O9>ROWS(Packets!$A$5:$A$404),"Exceeds Packets tab capacity","OK"))))))) -> OK | N9: Heartbeat and uptime. | O9: =SUM($F$5:$F9)+COUNTA($A$5:$A9) -> 43 | P9: =SUBSTITUTE($E9," ","") -> 42,43
A10: 0xE0 | B10: Witness Debug | C10: Witness -> peer | D10: 10 Hz nominal | E10: 0, 1, 2, 3, 8, 9, 10, 11, 12, 13, 14, 15, 16, 17, 18, 19, 20, 21, 22, 23, 24, 25, 26, 27, 28, 29, 30, 31, 32, 33, 34, 35, 36, 37 | F10: =IF($A10="","",IF($P10="",0,LEN($P10)-LEN(SUBSTITUTE($P10,",",""))+1)) -> 34 | G10: =IF($A10="","",SUMIFS(Packets!$G$5:$G$404,Packets!$L$5:$L$404,ROWS($A$5:$A10),Packets!$C$5:$C$404,"<="&$F10)) -> 101 | H10: =IF($A10="","",Overview!$B$27) -> 1 | I10: =IF($A10="","",Overview!$B$26) -> 1 | J10: =IF($A10="","",G10+H10+I10) -> 103 | K10: =IF($A10="","",ROUNDUP(J10/Overview!$B$28,0)) -> 13 | L10: =IF($A10="","",Overview!$B$29) -> 0 | M10: =IF(AND($A10="",$E10=""),"",IF($A10="","Enter a Packet ID",IF(COUNTIF($A$5:$A$34,$A10)>1,"Duplicate Packet ID",IF($F10=0,"No Field IDs entered",IF(SUMPRODUCT(--ISNUMBER(FIND(","&Fields!$A$5:$A$48&",",","&$P10&",")))<>$F10,"Check Field IDs: unknown, blank, or repeated",IF(COUNTIFS(Packets!$L$5:$L$404,ROWS($A$5:$A10),Packets!$D$5:$D$404,"ERR")+COUNTIFS(Packets!$L$5:$L$404,ROWS($A$5:$A10),Packets!$E$5:$E$404,"MISSING")>0,"Layout error: see Packets tab",IF($O10>ROWS(Packets!$A$5:$A$404),"Exceeds Packets tab capacity","OK"))))))) -> OK | N10: Every field collected from sensors and computed from witness. For debug only, command 0x64 to turn on, 0x65 to turn off. | O10: =SUM($F$5:$F10)+COUNTA($A$5:$A10) -> 78 | P10: =SUBSTITUTE($E10," ","") -> 0,1,2,3,8,9,10,11,12,13,14,15,16,17,18,19,20,21,22,23,24,25,26,27,28,29,30,31,32,33,34,35,36,37
A11: 0xE1 | B11: Iris debug | C11: Iris->peer | D11: 10 Hz nominal | E11: 5, 4, 6, 7, 38, 39, 40 | F11: =IF($A11="","",IF($P11="",0,LEN($P11)-LEN(SUBSTITUTE($P11,",",""))+1)) -> 7 | G11: =IF($A11="","",SUMIFS(Packets!$G$5:$G$404,Packets!$L$5:$L$404,ROWS($A$5:$A11),Packets!$C$5:$C$404,"<="&$F11)) -> 12 | H11: =IF($A11="","",Overview!$B$27) -> 1 | I11: =IF($A11="","",Overview!$B$26) -> 1 | J11: =IF($A11="","",G11+H11+I11) -> 14 | K11: =IF($A11="","",ROUNDUP(J11/Overview!$B$28,0)) -> 2 | L11: =IF($A11="","",Overview!$B$29) -> 0 | M11: =IF(AND($A11="",$E11=""),"",IF($A11="","Enter a Packet ID",IF(COUNTIF($A$5:$A$34,$A11)>1,"Duplicate Packet ID",IF($F11=0,"No Field IDs entered",IF(SUMPRODUCT(--ISNUMBER(FIND(","&Fields!$A$5:$A$48&",",","&$P11&",")))<>$F11,"Check Field IDs: unknown, blank, or repeated",IF(COUNTIFS(Packets!$L$5:$L$404,ROWS($A$5:$A11),Packets!$D$5:$D$404,"ERR")+COUNTIFS(Packets!$L$5:$L$404,ROWS($A$5:$A11),Packets!$E$5:$E$404,"MISSING")>0,"Layout error: see Packets tab",IF($O11>ROWS(Packets!$A$5:$A$404),"Exceeds Packets tab capacity","OK"))))))) -> OK | N11: Every field collected from sensors and computed from Iris. For debug only, command 0x64 to turn on, 0x65 to turn off. | O11: =SUM($F$5:$F11)+COUNTA($A$5:$A11) -> 86 | P11: =SUBSTITUTE($E11," ","") -> 5,4,6,7,38,39,40
F12: =IF($A12="","",IF($P12="",0,LEN($P12)-LEN(SUBSTITUTE($P12,",",""))+1)) | G12: =IF($A12="","",SUMIFS(Packets!$G$5:$G$404,Packets!$L$5:$L$404,ROWS($A$5:$A12),Packets!$C$5:$C$404,"<="&$F12)) | H12: =IF($A12="","",Overview!$B$27) | I12: =IF($A12="","",Overview!$B$26) | J12: =IF($A12="","",G12+H12+I12) | K12: =IF($A12="","",ROUNDUP(J12/Overview!$B$28,0)) | L12: =IF($A12="","",Overview!$B$29) | M12: =IF(AND($A12="",$E12=""),"",IF($A12="","Enter a Packet ID",IF(COUNTIF($A$5:$A$34,$A12)>1,"Duplicate Packet ID",IF($F12=0,"No Field IDs entered",IF(SUMPRODUCT(--ISNUMBER(FIND(","&Fields!$A$5:$A$48&",",","&$P12&",")))<>$F12,"Check Field IDs: unknown, blank, or repeated",IF(COUNTIFS(Packets!$L$5:$L$404,ROWS($A$5:$A12),Packets!$D$5:$D$404,"ERR")+COUNTIFS(Packets!$L$5:$L$404,ROWS($A$5:$A12),Packets!$E$5:$E$404,"MISSING")>0,"Layout error: see Packets tab",IF($O12>ROWS(Packets!$A$5:$A$404),"Exceeds Packets tab capacity","OK"))))))) | O12: =SUM($F$5:$F12)+COUNTA($A$5:$A12) -> 86 | P12: =SUBSTITUTE($E12," ","")
F13: =IF($A13="","",IF($P13="",0,LEN($P13)-LEN(SUBSTITUTE($P13,",",""))+1)) | G13: =IF($A13="","",SUMIFS(Packets!$G$5:$G$404,Packets!$L$5:$L$404,ROWS($A$5:$A13),Packets!$C$5:$C$404,"<="&$F13)) | H13: =IF($A13="","",Overview!$B$27) | I13: =IF($A13="","",Overview!$B$26) | J13: =IF($A13="","",G13+H13+I13) | K13: =IF($A13="","",ROUNDUP(J13/Overview!$B$28,0)) | L13: =IF($A13="","",Overview!$B$29) | M13: =IF(AND($A13="",$E13=""),"",IF($A13="","Enter a Packet ID",IF(COUNTIF($A$5:$A$34,$A13)>1,"Duplicate Packet ID",IF($F13=0,"No Field IDs entered",IF(SUMPRODUCT(--ISNUMBER(FIND(","&Fields!$A$5:$A$48&",",","&$P13&",")))<>$F13,"Check Field IDs: unknown, blank, or repeated",IF(COUNTIFS(Packets!$L$5:$L$404,ROWS($A$5:$A13),Packets!$D$5:$D$404,"ERR")+COUNTIFS(Packets!$L$5:$L$404,ROWS($A$5:$A13),Packets!$E$5:$E$404,"MISSING")>0,"Layout error: see Packets tab",IF($O13>ROWS(Packets!$A$5:$A$404),"Exceeds Packets tab capacity","OK"))))))) | O13: =SUM($F$5:$F13)+COUNTA($A$5:$A13) -> 86 | P13: =SUBSTITUTE($E13," ","")
F14: =IF($A14="","",IF($P14="",0,LEN($P14)-LEN(SUBSTITUTE($P14,",",""))+1)) | G14: =IF($A14="","",SUMIFS(Packets!$G$5:$G$404,Packets!$L$5:$L$404,ROWS($A$5:$A14),Packets!$C$5:$C$404,"<="&$F14)) | H14: =IF($A14="","",Overview!$B$27) | I14: =IF($A14="","",Overview!$B$26) | J14: =IF($A14="","",G14+H14+I14) | K14: =IF($A14="","",ROUNDUP(J14/Overview!$B$28,0)) | L14: =IF($A14="","",Overview!$B$29) | M14: =IF(AND($A14="",$E14=""),"",IF($A14="","Enter a Packet ID",IF(COUNTIF($A$5:$A$34,$A14)>1,"Duplicate Packet ID",IF($F14=0,"No Field IDs entered",IF(SUMPRODUCT(--ISNUMBER(FIND(","&Fields!$A$5:$A$48&",",","&$P14&",")))<>$F14,"Check Field IDs: unknown, blank, or repeated",IF(COUNTIFS(Packets!$L$5:$L$404,ROWS($A$5:$A14),Packets!$D$5:$D$404,"ERR")+COUNTIFS(Packets!$L$5:$L$404,ROWS($A$5:$A14),Packets!$E$5:$E$404,"MISSING")>0,"Layout error: see Packets tab",IF($O14>ROWS(Packets!$A$5:$A$404),"Exceeds Packets tab capacity","OK"))))))) | O14: =SUM($F$5:$F14)+COUNTA($A$5:$A14) -> 86 | P14: =SUBSTITUTE($E14," ","")
F15: =IF($A15="","",IF($P15="",0,LEN($P15)-LEN(SUBSTITUTE($P15,",",""))+1)) | G15: =IF($A15="","",SUMIFS(Packets!$G$5:$G$404,Packets!$L$5:$L$404,ROWS($A$5:$A15),Packets!$C$5:$C$404,"<="&$F15)) | H15: =IF($A15="","",Overview!$B$27) | I15: =IF($A15="","",Overview!$B$26) | J15: =IF($A15="","",G15+H15+I15) | K15: =IF($A15="","",ROUNDUP(J15/Overview!$B$28,0)) | L15: =IF($A15="","",Overview!$B$29) | M15: =IF(AND($A15="",$E15=""),"",IF($A15="","Enter a Packet ID",IF(COUNTIF($A$5:$A$34,$A15)>1,"Duplicate Packet ID",IF($F15=0,"No Field IDs entered",IF(SUMPRODUCT(--ISNUMBER(FIND(","&Fields!$A$5:$A$48&",",","&$P15&",")))<>$F15,"Check Field IDs: unknown, blank, or repeated",IF(COUNTIFS(Packets!$L$5:$L$404,ROWS($A$5:$A15),Packets!$D$5:$D$404,"ERR")+COUNTIFS(Packets!$L$5:$L$404,ROWS($A$5:$A15),Packets!$E$5:$E$404,"MISSING")>0,"Layout error: see Packets tab",IF($O15>ROWS(Packets!$A$5:$A$404),"Exceeds Packets tab capacity","OK"))))))) | O15: =SUM($F$5:$F15)+COUNTA($A$5:$A15) -> 86 | P15: =SUBSTITUTE($E15," ","")
F16: =IF($A16="","",IF($P16="",0,LEN($P16)-LEN(SUBSTITUTE($P16,",",""))+1)) | G16: =IF($A16="","",SUMIFS(Packets!$G$5:$G$404,Packets!$L$5:$L$404,ROWS($A$5:$A16),Packets!$C$5:$C$404,"<="&$F16)) | H16: =IF($A16="","",Overview!$B$27) | I16: =IF($A16="","",Overview!$B$26) | J16: =IF($A16="","",G16+H16+I16) | K16: =IF($A16="","",ROUNDUP(J16/Overview!$B$28,0)) | L16: =IF($A16="","",Overview!$B$29) | M16: =IF(AND($A16="",$E16=""),"",IF($A16="","Enter a Packet ID",IF(COUNTIF($A$5:$A$34,$A16)>1,"Duplicate Packet ID",IF($F16=0,"No Field IDs entered",IF(SUMPRODUCT(--ISNUMBER(FIND(","&Fields!$A$5:$A$48&",",","&$P16&",")))<>$F16,"Check Field IDs: unknown, blank, or repeated",IF(COUNTIFS(Packets!$L$5:$L$404,ROWS($A$5:$A16),Packets!$D$5:$D$404,"ERR")+COUNTIFS(Packets!$L$5:$L$404,ROWS($A$5:$A16),Packets!$E$5:$E$404,"MISSING")>0,"Layout error: see Packets tab",IF($O16>ROWS(Packets!$A$5:$A$404),"Exceeds Packets tab capacity","OK"))))))) | O16: =SUM($F$5:$F16)+COUNTA($A$5:$A16) -> 86 | P16: =SUBSTITUTE($E16," ","")
F17: =IF($A17="","",IF($P17="",0,LEN($P17)-LEN(SUBSTITUTE($P17,",",""))+1)) | G17: =IF($A17="","",SUMIFS(Packets!$G$5:$G$404,Packets!$L$5:$L$404,ROWS($A$5:$A17),Packets!$C$5:$C$404,"<="&$F17)) | H17: =IF($A17="","",Overview!$B$27) | I17: =IF($A17="","",Overview!$B$26) | J17: =IF($A17="","",G17+H17+I17) | K17: =IF($A17="","",ROUNDUP(J17/Overview!$B$28,0)) | L17: =IF($A17="","",Overview!$B$29) | M17: =IF(AND($A17="",$E17=""),"",IF($A17="","Enter a Packet ID",IF(COUNTIF($A$5:$A$34,$A17)>1,"Duplicate Packet ID",IF($F17=0,"No Field IDs entered",IF(SUMPRODUCT(--ISNUMBER(FIND(","&Fields!$A$5:$A$48&",",","&$P17&",")))<>$F17,"Check Field IDs: unknown, blank, or repeated",IF(COUNTIFS(Packets!$L$5:$L$404,ROWS($A$5:$A17),Packets!$D$5:$D$404,"ERR")+COUNTIFS(Packets!$L$5:$L$404,ROWS($A$5:$A17),Packets!$E$5:$E$404,"MISSING")>0,"Layout error: see Packets tab",IF($O17>ROWS(Packets!$A$5:$A$404),"Exceeds Packets tab capacity","OK"))))))) | O17: =SUM($F$5:$F17)+COUNTA($A$5:$A17) -> 86 | P17: =SUBSTITUTE($E17," ","")
F18: =IF($A18="","",IF($P18="",0,LEN($P18)-LEN(SUBSTITUTE($P18,",",""))+1)) | G18: =IF($A18="","",SUMIFS(Packets!$G$5:$G$404,Packets!$L$5:$L$404,ROWS($A$5:$A18),Packets!$C$5:$C$404,"<="&$F18)) | H18: =IF($A18="","",Overview!$B$27) | I18: =IF($A18="","",Overview!$B$26) | J18: =IF($A18="","",G18+H18+I18) | K18: =IF($A18="","",ROUNDUP(J18/Overview!$B$28,0)) | L18: =IF($A18="","",Overview!$B$29) | M18: =IF(AND($A18="",$E18=""),"",IF($A18="","Enter a Packet ID",IF(COUNTIF($A$5:$A$34,$A18)>1,"Duplicate Packet ID",IF($F18=0,"No Field IDs entered",IF(SUMPRODUCT(--ISNUMBER(FIND(","&Fields!$A$5:$A$48&",",","&$P18&",")))<>$F18,"Check Field IDs: unknown, blank, or repeated",IF(COUNTIFS(Packets!$L$5:$L$404,ROWS($A$5:$A18),Packets!$D$5:$D$404,"ERR")+COUNTIFS(Packets!$L$5:$L$404,ROWS($A$5:$A18),Packets!$E$5:$E$404,"MISSING")>0,"Layout error: see Packets tab",IF($O18>ROWS(Packets!$A$5:$A$404),"Exceeds Packets tab capacity","OK"))))))) | O18: =SUM($F$5:$F18)+COUNTA($A$5:$A18) -> 86 | P18: =SUBSTITUTE($E18," ","")
F19: =IF($A19="","",IF($P19="",0,LEN($P19)-LEN(SUBSTITUTE($P19,",",""))+1)) | G19: =IF($A19="","",SUMIFS(Packets!$G$5:$G$404,Packets!$L$5:$L$404,ROWS($A$5:$A19),Packets!$C$5:$C$404,"<="&$F19)) | H19: =IF($A19="","",Overview!$B$27) | I19: =IF($A19="","",Overview!$B$26) | J19: =IF($A19="","",G19+H19+I19) | K19: =IF($A19="","",ROUNDUP(J19/Overview!$B$28,0)) | L19: =IF($A19="","",Overview!$B$29) | M19: =IF(AND($A19="",$E19=""),"",IF($A19="","Enter a Packet ID",IF(COUNTIF($A$5:$A$34,$A19)>1,"Duplicate Packet ID",IF($F19=0,"No Field IDs entered",IF(SUMPRODUCT(--ISNUMBER(FIND(","&Fields!$A$5:$A$48&",",","&$P19&",")))<>$F19,"Check Field IDs: unknown, blank, or repeated",IF(COUNTIFS(Packets!$L$5:$L$404,ROWS($A$5:$A19),Packets!$D$5:$D$404,"ERR")+COUNTIFS(Packets!$L$5:$L$404,ROWS($A$5:$A19),Packets!$E$5:$E$404,"MISSING")>0,"Layout error: see Packets tab",IF($O19>ROWS(Packets!$A$5:$A$404),"Exceeds Packets tab capacity","OK"))))))) | O19: =SUM($F$5:$F19)+COUNTA($A$5:$A19) -> 86 | P19: =SUBSTITUTE($E19," ","")
F20: =IF($A20="","",IF($P20="",0,LEN($P20)-LEN(SUBSTITUTE($P20,",",""))+1)) | G20: =IF($A20="","",SUMIFS(Packets!$G$5:$G$404,Packets!$L$5:$L$404,ROWS($A$5:$A20),Packets!$C$5:$C$404,"<="&$F20)) | H20: =IF($A20="","",Overview!$B$27) | I20: =IF($A20="","",Overview!$B$26) | J20: =IF($A20="","",G20+H20+I20) | K20: =IF($A20="","",ROUNDUP(J20/Overview!$B$28,0)) | L20: =IF($A20="","",Overview!$B$29) | M20: =IF(AND($A20="",$E20=""),"",IF($A20="","Enter a Packet ID",IF(COUNTIF($A$5:$A$34,$A20)>1,"Duplicate Packet ID",IF($F20=0,"No Field IDs entered",IF(SUMPRODUCT(--ISNUMBER(FIND(","&Fields!$A$5:$A$48&",",","&$P20&",")))<>$F20,"Check Field IDs: unknown, blank, or repeated",IF(COUNTIFS(Packets!$L$5:$L$404,ROWS($A$5:$A20),Packets!$D$5:$D$404,"ERR")+COUNTIFS(Packets!$L$5:$L$404,ROWS($A$5:$A20),Packets!$E$5:$E$404,"MISSING")>0,"Layout error: see Packets tab",IF($O20>ROWS(Packets!$A$5:$A$404),"Exceeds Packets tab capacity","OK"))))))) | O20: =SUM($F$5:$F20)+COUNTA($A$5:$A20) -> 86 | P20: =SUBSTITUTE($E20," ","")
F21: =IF($A21="","",IF($P21="",0,LEN($P21)-LEN(SUBSTITUTE($P21,",",""))+1)) | G21: =IF($A21="","",SUMIFS(Packets!$G$5:$G$404,Packets!$L$5:$L$404,ROWS($A$5:$A21),Packets!$C$5:$C$404,"<="&$F21)) | H21: =IF($A21="","",Overview!$B$27) | I21: =IF($A21="","",Overview!$B$26) | J21: =IF($A21="","",G21+H21+I21) | K21: =IF($A21="","",ROUNDUP(J21/Overview!$B$28,0)) | L21: =IF($A21="","",Overview!$B$29) | M21: =IF(AND($A21="",$E21=""),"",IF($A21="","Enter a Packet ID",IF(COUNTIF($A$5:$A$34,$A21)>1,"Duplicate Packet ID",IF($F21=0,"No Field IDs entered",IF(SUMPRODUCT(--ISNUMBER(FIND(","&Fields!$A$5:$A$48&",",","&$P21&",")))<>$F21,"Check Field IDs: unknown, blank, or repeated",IF(COUNTIFS(Packets!$L$5:$L$404,ROWS($A$5:$A21),Packets!$D$5:$D$404,"ERR")+COUNTIFS(Packets!$L$5:$L$404,ROWS($A$5:$A21),Packets!$E$5:$E$404,"MISSING")>0,"Layout error: see Packets tab",IF($O21>ROWS(Packets!$A$5:$A$404),"Exceeds Packets tab capacity","OK"))))))) | O21: =SUM($F$5:$F21)+COUNTA($A$5:$A21) -> 86 | P21: =SUBSTITUTE($E21," ","")
F22: =IF($A22="","",IF($P22="",0,LEN($P22)-LEN(SUBSTITUTE($P22,",",""))+1)) | G22: =IF($A22="","",SUMIFS(Packets!$G$5:$G$404,Packets!$L$5:$L$404,ROWS($A$5:$A22),Packets!$C$5:$C$404,"<="&$F22)) | H22: =IF($A22="","",Overview!$B$27) | I22: =IF($A22="","",Overview!$B$26) | J22: =IF($A22="","",G22+H22+I22) | K22: =IF($A22="","",ROUNDUP(J22/Overview!$B$28,0)) | L22: =IF($A22="","",Overview!$B$29) | M22: =IF(AND($A22="",$E22=""),"",IF($A22="","Enter a Packet ID",IF(COUNTIF($A$5:$A$34,$A22)>1,"Duplicate Packet ID",IF($F22=0,"No Field IDs entered",IF(SUMPRODUCT(--ISNUMBER(FIND(","&Fields!$A$5:$A$48&",",","&$P22&",")))<>$F22,"Check Field IDs: unknown, blank, or repeated",IF(COUNTIFS(Packets!$L$5:$L$404,ROWS($A$5:$A22),Packets!$D$5:$D$404,"ERR")+COUNTIFS(Packets!$L$5:$L$404,ROWS($A$5:$A22),Packets!$E$5:$E$404,"MISSING")>0,"Layout error: see Packets tab",IF($O22>ROWS(Packets!$A$5:$A$404),"Exceeds Packets tab capacity","OK"))))))) | O22: =SUM($F$5:$F22)+COUNTA($A$5:$A22) -> 86 | P22: =SUBSTITUTE($E22," ","")
F23: =IF($A23="","",IF($P23="",0,LEN($P23)-LEN(SUBSTITUTE($P23,",",""))+1)) | G23: =IF($A23="","",SUMIFS(Packets!$G$5:$G$404,Packets!$L$5:$L$404,ROWS($A$5:$A23),Packets!$C$5:$C$404,"<="&$F23)) | H23: =IF($A23="","",Overview!$B$27) | I23: =IF($A23="","",Overview!$B$26) | J23: =IF($A23="","",G23+H23+I23) | K23: =IF($A23="","",ROUNDUP(J23/Overview!$B$28,0)) | L23: =IF($A23="","",Overview!$B$29) | M23: =IF(AND($A23="",$E23=""),"",IF($A23="","Enter a Packet ID",IF(COUNTIF($A$5:$A$34,$A23)>1,"Duplicate Packet ID",IF($F23=0,"No Field IDs entered",IF(SUMPRODUCT(--ISNUMBER(FIND(","&Fields!$A$5:$A$48&",",","&$P23&",")))<>$F23,"Check Field IDs: unknown, blank, or repeated",IF(COUNTIFS(Packets!$L$5:$L$404,ROWS($A$5:$A23),Packets!$D$5:$D$404,"ERR")+COUNTIFS(Packets!$L$5:$L$404,ROWS($A$5:$A23),Packets!$E$5:$E$404,"MISSING")>0,"Layout error: see Packets tab",IF($O23>ROWS(Packets!$A$5:$A$404),"Exceeds Packets tab capacity","OK"))))))) | O23: =SUM($F$5:$F23)+COUNTA($A$5:$A23) -> 86 | P23: =SUBSTITUTE($E23," ","")
... F34: =IF($A34="","",IF($P34="",0,LEN($P34)-LEN(SUBSTITUTE($P34,",",""))+1)) | G34: =IF($A34="","",SUMIFS(Packets!$G$5:$G$404,Packets!$L$5:$L$404,ROWS($A$5:$A34),Packets!$C$5:$C$404,"<="&$F34)) | H34: =IF($A34="","",Overview!$B$27) | I34: =IF($A34="","",Overview!$B$26) | J34: =IF($A34="","",G34+H34+I34) | K34: =IF($A34="","",ROUNDUP(J34/Overview!$B$28,0)) | L34: =IF($A34="","",Overview!$B$29) | M34: =IF(AND($A34="",$E34=""),"",IF($A34="","Enter a Packet ID",IF(COUNTIF($A$5:$A$34,$A34)>1,"Duplicate Packet ID",IF($F34=0,"No Field IDs entered",IF(SUMPRODUCT(--ISNUMBER(FIND(","&Fields!$A$5:$A$48&",",","&$P34&",")))<>$F34,"Check Field IDs: unknown, blank, or repeated",IF(COUNTIFS(Packets!$L$5:$L$404,ROWS($A$5:$A34),Packets!$D$5:$D$404,"ERR")+COUNTIFS(Packets!$L$5:$L$404,ROWS($A$5:$A34),Packets!$E$5:$E$404,"MISSING")>0,"Layout error: see Packets tab",IF($O34>ROWS(Packets!$A$5:$A$404),"Exceeds Packets tab capacity","OK"))))))) | O34: =SUM($F$5:$F34)+COUNTA($A$5:$A34) -> 86 | P34: =SUBSTITUTE($E34," ","")

Sheet Packets
A1: Canonical Packet Definitions
A2: Generated from the Packet Builder tab: edit packets there, not here. Packet IDs, field orders, offsets, and payload sizes are identical on every transport. Offsets count from the first payload byte (right after the packet ID); the highlighted row is the end-of-frame delimiter.
A4: Packet ID | B4: Packet | C4: Order | D4: Field ID | E4: Field | F4: Offset | G4: Size bytes | H4: Last byte | I4: Wire type | J4: Scale / interpretation | K4: C definition | L4: Builder row (helper) | M4: Fields in packet (helper)
A5: =IF($L5="","",INDEX('Packet Builder'!$A$5:$A$34,$L5)) -> 0x01 | B5: =IF($L5="","",INDEX('Packet Builder'!$B$5:$B$34,$L5)) -> Sensors | C5: =IF($L5="","",ROWS($L$5:L5)-(INDEX('Packet Builder'!$O$5:$O$34,$L5)-$M5-1)) -> 1 | D5: =IF($L5="","",IF($C5>$M5,"EOF",IFERROR(VALUE(TRIM(MID(SUBSTITUTE(INDEX('Packet Builder'!$P$5:$P$34,$L5),",",REPT(" ",LEN(INDEX('Packet Builder'!$P$5:$P$34,$L5)))),($C5-1)*LEN(INDEX('Packet Builder'!$P$5:$P$34,$L5))+1,LEN(INDEX('Packet Builder'!$P$5:$P$34,$L5))))),"ERR"))) -> 0 | E5: =IF($L5="","",IF($C5>$M5,"End of Frame Delimiter",IFERROR(INDEX(Fields!$B$5:$B$48,MATCH($D5,Fields!$A$5:$A$48,0)),"MISSING"))) -> Witness Status | F5: =IF($L5="","",SUMIF($L$5:L5,L5,$G$5:G5)-G5) -> 0 | G5: =IF($L5="","",IF($C5>$M5,Overview!$B$26,IFERROR(INDEX(Fields!$F$5:$F$48,MATCH($D5,Fields!$A$5:$A$48,0)),0))) -> 2 | H5: =IF($L5="","",F5+G5-1) -> 1 | I5: =IF($L5="","",IF($C5>$M5,IF(Overview!$B$26=1,"uint8","uint8["&Overview!$B$26&"]"),IFERROR(INDEX(Fields!$E$5:$E$48,MATCH($D5,Fields!$A$5:$A$48,0)),"MISSING"))) -> bitfield[16] | J5: =IF($L5="","",IF($C5>$M5,"Fixed end-of-frame delimiter, value "&Overview!$B$25&".",IFERROR(INDEX(Fields!$G$5:$G$48,MATCH($D5,Fields!$A$5:$A$48,0)),"MISSING"))) -> Byte 0 contains status flags; byte 1 is reserved. No numeric scale. | K5: =IF($L5="","",IF($C5>$M5,"n/a",IFERROR(INDEX(Fields!$H$5:$H$48,MATCH($D5,Fields!$A$5:$A$48,0)),"MISSING"))) -> IRIS_FIELD_WITNESS_STATUS_LENGTH | L5: =IF(ROWS($L$5:L5)>MAX('Packet Builder'!$O$5:$O$34),"",COUNTIF('Packet Builder'!$O$5:$O$34,"<"&ROWS($L$5:L5))+1) -> 1 | M5: =IF($L5="","",INDEX('Packet Builder'!$F$5:$F$34,$L5)) -> 8
A6: =IF($L6="","",INDEX('Packet Builder'!$A$5:$A$34,$L6)) -> 0x01 | B6: =IF($L6="","",INDEX('Packet Builder'!$B$5:$B$34,$L6)) -> Sensors | C6: =IF($L6="","",ROWS($L$5:L6)-(INDEX('Packet Builder'!$O$5:$O$34,$L6)-$M6-1)) -> 2 | D6: =IF($L6="","",IF($C6>$M6,"EOF",IFERROR(VALUE(TRIM(MID(SUBSTITUTE(INDEX('Packet Builder'!$P$5:$P$34,$L6),",",REPT(" ",LEN(INDEX('Packet Builder'!$P$5:$P$34,$L6)))),($C6-1)*LEN(INDEX('Packet Builder'!$P$5:$P$34,$L6))+1,LEN(INDEX('Packet Builder'!$P$5:$P$34,$L6))))),"ERR"))) -> 1 | E6: =IF($L6="","",IF($C6>$M6,"End of Frame Delimiter",IFERROR(INDEX(Fields!$B$5:$B$48,MATCH($D6,Fields!$A$5:$A$48,0)),"MISSING"))) -> Witness Uptime | F6: =IF($L6="","",SUMIF($L$5:L6,L6,$G$5:G6)-G6) -> 2 | G6: =IF($L6="","",IF($C6>$M6,Overview!$B$26,IFERROR(INDEX(Fields!$F$5:$F$48,MATCH($D6,Fields!$A$5:$A$48,0)),0))) -> 4 | H6: =IF($L6="","",F6+G6-1) -> 5 | I6: =IF($L6="","",IF($C6>$M6,IF(Overview!$B$26=1,"uint8","uint8["&Overview!$B$26&"]"),IFERROR(INDEX(Fields!$E$5:$E$48,MATCH($D6,Fields!$A$5:$A$48,0)),"MISSING"))) -> uint32 | J6: =IF($L6="","",IF($C6>$M6,"Fixed end-of-frame delimiter, value "&Overview!$B$25&".",IFERROR(INDEX(Fields!$G$5:$G$48,MATCH($D6,Fields!$A$5:$A$48,0)),"MISSING"))) -> 1 ms/count; elapsed time since boot. | K6: =IF($L6="","",IF($C6>$M6,"n/a",IFERROR(INDEX(Fields!$H$5:$H$48,MATCH($D6,Fields!$A$5:$A$48,0)),"MISSING"))) -> IRIS_FIELD_WITNESS_UPTIME_LENGTH | L6: =IF(ROWS($L$5:L6)>MAX('Packet Builder'!$O$5:$O$34),"",COUNTIF('Packet Builder'!$O$5:$O$34,"<"&ROWS($L$5:L6))+1) -> 1 | M6: =IF($L6="","",INDEX('Packet Builder'!$F$5:$F$34,$L6)) -> 8
A7: =IF($L7="","",INDEX('Packet Builder'!$A$5:$A$34,$L7)) -> 0x01 | B7: =IF($L7="","",INDEX('Packet Builder'!$B$5:$B$34,$L7)) -> Sensors | C7: =IF($L7="","",ROWS($L$5:L7)-(INDEX('Packet Builder'!$O$5:$O$34,$L7)-$M7-1)) -> 3 | D7: =IF($L7="","",IF($C7>$M7,"EOF",IFERROR(VALUE(TRIM(MID(SUBSTITUTE(INDEX('Packet Builder'!$P$5:$P$34,$L7),",",REPT(" ",LEN(INDEX('Packet Builder'!$P$5:$P$34,$L7)))),($C7-1)*LEN(INDEX('Packet Builder'!$P$5:$P$34,$L7))+1,LEN(INDEX('Packet Builder'!$P$5:$P$34,$L7))))),"ERR"))) -> 8 | E7: =IF($L7="","",IF($C7>$M7,"End of Frame Delimiter",IFERROR(INDEX(Fields!$B$5:$B$48,MATCH($D7,Fields!$A$5:$A$48,0)),"MISSING"))) -> Filtered Accel X | F7: =IF($L7="","",SUMIF($L$5:L7,L7,$G$5:G7)-G7) -> 6 | G7: =IF($L7="","",IF($C7>$M7,Overview!$B$26,IFERROR(INDEX(Fields!$F$5:$F$48,MATCH($D7,Fields!$A$5:$A$48,0)),0))) -> 3 | H7: =IF($L7="","",F7+G7-1) -> 8 | I7: =IF($L7="","",IF($C7>$M7,IF(Overview!$B$26=1,"uint8","uint8["&Overview!$B$26&"]"),IFERROR(INDEX(Fields!$E$5:$E$48,MATCH($D7,Fields!$A$5:$A$48,0)),"MISSING"))) -> signed int24 | J7: =IF($L7="","",IF($C7>$M7,"Fixed end-of-frame delimiter, value "&Overview!$B$25&".",IFERROR(INDEX(Fields!$G$5:$G$48,MATCH($D7,Fields!$A$5:$A$48,0)),"MISSING"))) -> 40 micro-g/count; acceleration in g = raw x 0.000040; range approximately -335.54 to +335.54 g. | K7: =IF($L7="","",IF($C7>$M7,"n/a",IFERROR(INDEX(Fields!$H$5:$H$48,MATCH($D7,Fields!$A$5:$A$48,0)),"MISSING"))) -> IRIS_FIELD_FILTERED_ACCEL_X_LENGTH | L7: =IF(ROWS($L$5:L7)>MAX('Packet Builder'!$O$5:$O$34),"",COUNTIF('Packet Builder'!$O$5:$O$34,"<"&ROWS($L$5:L7))+1) -> 1 | M7: =IF($L7="","",INDEX('Packet Builder'!$F$5:$F$34,$L7)) -> 8
A8: =IF($L8="","",INDEX('Packet Builder'!$A$5:$A$34,$L8)) -> 0x01 | B8: =IF($L8="","",INDEX('Packet Builder'!$B$5:$B$34,$L8)) -> Sensors | C8: =IF($L8="","",ROWS($L$5:L8)-(INDEX('Packet Builder'!$O$5:$O$34,$L8)-$M8-1)) -> 4 | D8: =IF($L8="","",IF($C8>$M8,"EOF",IFERROR(VALUE(TRIM(MID(SUBSTITUTE(INDEX('Packet Builder'!$P$5:$P$34,$L8),",",REPT(" ",LEN(INDEX('Packet Builder'!$P$5:$P$34,$L8)))),($C8-1)*LEN(INDEX('Packet Builder'!$P$5:$P$34,$L8))+1,LEN(INDEX('Packet Builder'!$P$5:$P$34,$L8))))),"ERR"))) -> 9 | E8: =IF($L8="","",IF($C8>$M8,"End of Frame Delimiter",IFERROR(INDEX(Fields!$B$5:$B$48,MATCH($D8,Fields!$A$5:$A$48,0)),"MISSING"))) -> Filtered Accel Y | F8: =IF($L8="","",SUMIF($L$5:L8,L8,$G$5:G8)-G8) -> 9 | G8: =IF($L8="","",IF($C8>$M8,Overview!$B$26,IFERROR(INDEX(Fields!$F$5:$F$48,MATCH($D8,Fields!$A$5:$A$48,0)),0))) -> 3 | H8: =IF($L8="","",F8+G8-1) -> 11 | I8: =IF($L8="","",IF($C8>$M8,IF(Overview!$B$26=1,"uint8","uint8["&Overview!$B$26&"]"),IFERROR(INDEX(Fields!$E$5:$E$48,MATCH($D8,Fields!$A$5:$A$48,0)),"MISSING"))) -> signed int24 | J8: =IF($L8="","",IF($C8>$M8,"Fixed end-of-frame delimiter, value "&Overview!$B$25&".",IFERROR(INDEX(Fields!$G$5:$G$48,MATCH($D8,Fields!$A$5:$A$48,0)),"MISSING"))) -> 40 micro-g/count; acceleration in g = raw x 0.000040; range approximately -335.54 to +335.54 g. | K8: =IF($L8="","",IF($C8>$M8,"n/a",IFERROR(INDEX(Fields!$H$5:$H$48,MATCH($D8,Fields!$A$5:$A$48,0)),"MISSING"))) -> IRIS_FIELD_FILTERED_ACCEL_Y_LENGTH | L8: =IF(ROWS($L$5:L8)>MAX('Packet Builder'!$O$5:$O$34),"",COUNTIF('Packet Builder'!$O$5:$O$34,"<"&ROWS($L$5:L8))+1) -> 1 | M8: =IF($L8="","",INDEX('Packet Builder'!$F$5:$F$34,$L8)) -> 8
A9: =IF($L9="","",INDEX('Packet Builder'!$A$5:$A$34,$L9)) -> 0x01 | B9: =IF($L9="","",INDEX('Packet Builder'!$B$5:$B$34,$L9)) -> Sensors | C9: =IF($L9="","",ROWS($L$5:L9)-(INDEX('Packet Builder'!$O$5:$O$34,$L9)-$M9-1)) -> 5 | D9: =IF($L9="","",IF($C9>$M9,"EOF",IFERROR(VALUE(TRIM(MID(SUBSTITUTE(INDEX('Packet Builder'!$P$5:$P$34,$L9),",",REPT(" ",LEN(INDEX('Packet Builder'!$P$5:$P$34,$L9)))),($C9-1)*LEN(INDEX('Packet Builder'!$P$5:$P$34,$L9))+1,LEN(INDEX('Packet Builder'!$P$5:$P$34,$L9))))),"ERR"))) -> 10 | E9: =IF($L9="","",IF($C9>$M9,"End of Frame Delimiter",IFERROR(INDEX(Fields!$B$5:$B$48,MATCH($D9,Fields!$A$5:$A$48,0)),"MISSING"))) -> Filtered Accel Z | F9: =IF($L9="","",SUMIF($L$5:L9,L9,$G$5:G9)-G9) -> 12 | G9: =IF($L9="","",IF($C9>$M9,Overview!$B$26,IFERROR(INDEX(Fields!$F$5:$F$48,MATCH($D9,Fields!$A$5:$A$48,0)),0))) -> 3 | H9: =IF($L9="","",F9+G9-1) -> 14 | I9: =IF($L9="","",IF($C9>$M9,IF(Overview!$B$26=1,"uint8","uint8["&Overview!$B$26&"]"),IFERROR(INDEX(Fields!$E$5:$E$48,MATCH($D9,Fields!$A$5:$A$48,0)),"MISSING"))) -> signed int24 | J9: =IF($L9="","",IF($C9>$M9,"Fixed end-of-frame delimiter, value "&Overview!$B$25&".",IFERROR(INDEX(Fields!$G$5:$G$48,MATCH($D9,Fields!$A$5:$A$48,0)),"MISSING"))) -> 40 micro-g/count; acceleration in g = raw x 0.000040; range approximately -335.54 to +335.54 g. | K9: =IF($L9="","",IF($C9>$M9,"n/a",IFERROR(INDEX(Fields!$H$5:$H$48,MATCH($D9,Fields!$A$5:$A$48,0)),"MISSING"))) -> IRIS_FIELD_FILTERED_ACCEL_Z_LENGTH | L9: =IF(ROWS($L$5:L9)>MAX('Packet Builder'!$O$5:$O$34),"",COUNTIF('Packet Builder'!$O$5:$O$34,"<"&ROWS($L$5:L9))+1) -> 1 | M9: =IF($L9="","",INDEX('Packet Builder'!$F$5:$F$34,$L9)) -> 8
A10: =IF($L10="","",INDEX('Packet Builder'!$A$5:$A$34,$L10)) -> 0x01 | B10: =IF($L10="","",INDEX('Packet Builder'!$B$5:$B$34,$L10)) -> Sensors | C10: =IF($L10="","",ROWS($L$5:L10)-(INDEX('Packet Builder'!$O$5:$O$34,$L10)-$M10-1)) -> 6 | D10: =IF($L10="","",IF($C10>$M10,"EOF",IFERROR(VALUE(TRIM(MID(SUBSTITUTE(INDEX('Packet Builder'!$P$5:$P$34,$L10),",",REPT(" ",LEN(INDEX('Packet Builder'!$P$5:$P$34,$L10)))),($C10-1)*LEN(INDEX('Packet Builder'!$P$5:$P$34,$L10))+1,LEN(INDEX('Packet Builder'!$P$5:$P$34,$L10))))),"ERR"))) -> 28 | E10: =IF($L10="","",IF($C10>$M10,"End of Frame Delimiter",IFERROR(INDEX(Fields!$B$5:$B$48,MATCH($D10,Fields!$A$5:$A$48,0)),"MISSING"))) -> LSM6 Gyro X | F10: =IF($L10="","",SUMIF($L$5:L10,L10,$G$5:G10)-G10) -> 15 | G10: =IF($L10="","",IF($C10>$M10,Overview!$B$26,IFERROR(INDEX(Fields!$F$5:$F$48,MATCH($D10,Fields!$A$5:$A$48,0)),0))) -> 2 | H10: =IF($L10="","",F10+G10-1) -> 16 | I10: =IF($L10="","",IF($C10>$M10,IF(Overview!$B$26=1,"uint8","uint8["&Overview!$B$26&"]"),IFERROR(INDEX(Fields!$E$5:$E$48,MATCH($D10,Fields!$A$5:$A$48,0)),"MISSING"))) -> int16 | J10: =IF($L10="","",IF($C10>$M10,"Fixed end-of-frame delimiter, value "&Overview!$B$25&".",IFERROR(INDEX(Fields!$G$5:$G$48,MATCH($D10,Fields!$A$5:$A$48,0)),"MISSING"))) -> 70 mdps/count at +/-2000 dps. | K10: =IF($L10="","",IF($C10>$M10,"n/a",IFERROR(INDEX(Fields!$H$5:$H$48,MATCH($D10,Fields!$A$5:$A$48,0)),"MISSING"))) -> IRIS_FIELD_LSM6_GYRO_X_LENGTH | L10: =IF(ROWS($L$5:L10)>MAX('Packet Builder'!$O$5:$O$34),"",COUNTIF('Packet Builder'!$O$5:$O$34,"<"&ROWS($L$5:L10))+1) -> 1 | M10: =IF($L10="","",INDEX('Packet Builder'!$F$5:$F$34,$L10)) -> 8
A11: =IF($L11="","",INDEX('Packet Builder'!$A$5:$A$34,$L11)) -> 0x01 | B11: =IF($L11="","",INDEX('Packet Builder'!$B$5:$B$34,$L11)) -> Sensors | C11: =IF($L11="","",ROWS($L$5:L11)-(INDEX('Packet Builder'!$O$5:$O$34,$L11)-$M11-1)) -> 7 | D11: =IF($L11="","",IF($C11>$M11,"EOF",IFERROR(VALUE(TRIM(MID(SUBSTITUTE(INDEX('Packet Builder'!$P$5:$P$34,$L11),",",REPT(" ",LEN(INDEX('Packet Builder'!$P$5:$P$34,$L11)))),($C11-1)*LEN(INDEX('Packet Builder'!$P$5:$P$34,$L11))+1,LEN(INDEX('Packet Builder'!$P$5:$P$34,$L11))))),"ERR"))) -> 29 | E11: =IF($L11="","",IF($C11>$M11,"End of Frame Delimiter",IFERROR(INDEX(Fields!$B$5:$B$48,MATCH($D11,Fields!$A$5:$A$48,0)),"MISSING"))) -> LSM6 Gyro Y | F11: =IF($L11="","",SUMIF($L$5:L11,L11,$G$5:G11)-G11) -> 17 | G11: =IF($L11="","",IF($C11>$M11,Overview!$B$26,IFERROR(INDEX(Fields!$F$5:$F$48,MATCH($D11,Fields!$A$5:$A$48,0)),0))) -> 2 | H11: =IF($L11="","",F11+G11-1) -> 18 | I11: =IF($L11="","",IF($C11>$M11,IF(Overview!$B$26=1,"uint8","uint8["&Overview!$B$26&"]"),IFERROR(INDEX(Fields!$E$5:$E$48,MATCH($D11,Fields!$A$5:$A$48,0)),"MISSING"))) -> int16 | J11: =IF($L11="","",IF($C11>$M11,"Fixed end-of-frame delimiter, value "&Overview!$B$25&".",IFERROR(INDEX(Fields!$G$5:$G$48,MATCH($D11,Fields!$A$5:$A$48,0)),"MISSING"))) -> 70 mdps/count at +/-2000 dps. | K11: =IF($L11="","",IF($C11>$M11,"n/a",IFERROR(INDEX(Fields!$H$5:$H$48,MATCH($D11,Fields!$A$5:$A$48,0)),"MISSING"))) -> IRIS_FIELD_LSM6_GYRO_Y_LENGTH | L11: =IF(ROWS($L$5:L11)>MAX('Packet Builder'!$O$5:$O$34),"",COUNTIF('Packet Builder'!$O$5:$O$34,"<"&ROWS($L$5:L11))+1) -> 1 | M11: =IF($L11="","",INDEX('Packet Builder'!$F$5:$F$34,$L11)) -> 8
A12: =IF($L12="","",INDEX('Packet Builder'!$A$5:$A$34,$L12)) -> 0x01 | B12: =IF($L12="","",INDEX('Packet Builder'!$B$5:$B$34,$L12)) -> Sensors | C12: =IF($L12="","",ROWS($L$5:L12)-(INDEX('Packet Builder'!$O$5:$O$34,$L12)-$M12-1)) -> 8 | D12: =IF($L12="","",IF($C12>$M12,"EOF",IFERROR(VALUE(TRIM(MID(SUBSTITUTE(INDEX('Packet Builder'!$P$5:$P$34,$L12),",",REPT(" ",LEN(INDEX('Packet Builder'!$P$5:$P$34,$L12)))),($C12-1)*LEN(INDEX('Packet Builder'!$P$5:$P$34,$L12))+1,LEN(INDEX('Packet Builder'!$P$5:$P$34,$L12))))),"ERR"))) -> 30 | E12: =IF($L12="","",IF($C12>$M12,"End of Frame Delimiter",IFERROR(INDEX(Fields!$B$5:$B$48,MATCH($D12,Fields!$A$5:$A$48,0)),"MISSING"))) -> LSM6 Gyro Z | F12: =IF($L12="","",SUMIF($L$5:L12,L12,$G$5:G12)-G12) -> 19 | G12: =IF($L12="","",IF($C12>$M12,Overview!$B$26,IFERROR(INDEX(Fields!$F$5:$F$48,MATCH($D12,Fields!$A$5:$A$48,0)),0))) -> 2 | H12: =IF($L12="","",F12+G12-1) -> 20 | I12: =IF($L12="","",IF($C12>$M12,IF(Overview!$B$26=1,"uint8","uint8["&Overview!$B$26&"]"),IFERROR(INDEX(Fields!$E$5:$E$48,MATCH($D12,Fields!$A$5:$A$48,0)),"MISSING"))) -> int16 | J12: =IF($L12="","",IF($C12>$M12,"Fixed end-of-frame delimiter, value "&Overview!$B$25&".",IFERROR(INDEX(Fields!$G$5:$G$48,MATCH($D12,Fields!$A$5:$A$48,0)),"MISSING"))) -> 70 mdps/count at +/-2000 dps. | K12: =IF($L12="","",IF($C12>$M12,"n/a",IFERROR(INDEX(Fields!$H$5:$H$48,MATCH($D12,Fields!$A$5:$A$48,0)),"MISSING"))) -> IRIS_FIELD_LSM6_GYRO_Z_LENGTH | L12: =IF(ROWS($L$5:L12)>MAX('Packet Builder'!$O$5:$O$34),"",COUNTIF('Packet Builder'!$O$5:$O$34,"<"&ROWS($L$5:L12))+1) -> 1 | M12: =IF($L12="","",INDEX('Packet Builder'!$F$5:$F$34,$L12)) -> 8
A13: =IF($L13="","",INDEX('Packet Builder'!$A$5:$A$34,$L13)) -> 0x01 | B13: =IF($L13="","",INDEX('Packet Builder'!$B$5:$B$34,$L13)) -> Sensors | C13: =IF($L13="","",ROWS($L$5:L13)-(INDEX('Packet Builder'!$O$5:$O$34,$L13)-$M13-1)) -> 9 | D13: =IF($L13="","",IF($C13>$M13,"EOF",IFERROR(VALUE(TRIM(MID(SUBSTITUTE(INDEX('Packet Builder'!$P$5:$P$34,$L13),",",REPT(" ",LEN(INDEX('Packet Builder'!$P$5:$P$34,$L13)))),($C13-1)*LEN(INDEX('Packet Builder'!$P$5:$P$34,$L13))+1,LEN(INDEX('Packet Builder'!$P$5:$P$34,$L13))))),"ERR"))) -> EOF | E13: =IF($L13="","",IF($C13>$M13,"End of Frame Delimiter",IFERROR(INDEX(Fields!$B$5:$B$48,MATCH($D13,Fields!$A$5:$A$48,0)),"MISSING"))) -> End of Frame Delimiter | F13: =IF($L13="","",SUMIF($L$5:L13,L13,$G$5:G13)-G13) -> 21 | G13: =IF($L13="","",IF($C13>$M13,Overview!$B$26,IFERROR(INDEX(Fields!$F$5:$F$48,MATCH($D13,Fields!$A$5:$A$48,0)),0))) -> 1 | H13: =IF($L13="","",F13+G13-1) -> 21 | I13: =IF($L13="","",IF($C13>$M13,IF(Overview!$B$26=1,"uint8","uint8["&Overview!$B$26&"]"),IFERROR(INDEX(Fields!$E$5:$E$48,MATCH($D13,Fields!$A$5:$A$48,0)),"MISSING"))) -> uint8 | J13: =IF($L13="","",IF($C13>$M13,"Fixed end-of-frame delimiter, value "&Overview!$B$25&".",IFERROR(INDEX(Fields!$G$5:$G$48,MATCH($D13,Fields!$A$5:$A$48,0)),"MISSING"))) -> Fixed end-of-frame delimiter, value 0x0A. | K13: =IF($L13="","",IF($C13>$M13,"n/a",IFERROR(INDEX(Fields!$H$5:$H$48,MATCH($D13,Fields!$A$5:$A$48,0)),"MISSING"))) -> n/a | L13: =IF(ROWS($L$5:L13)>MAX('Packet Builder'!$O$5:$O$34),"",COUNTIF('Packet Builder'!$O$5:$O$34,"<"&ROWS($L$5:L13))+1) -> 1 | M13: =IF($L13="","",INDEX('Packet Builder'!$F$5:$F$34,$L13)) -> 8
A14: =IF($L14="","",INDEX('Packet Builder'!$A$5:$A$34,$L14)) -> 0x02 | B14: =IF($L14="","",INDEX('Packet Builder'!$B$5:$B$34,$L14)) -> State | C14: =IF($L14="","",ROWS($L$5:L14)-(INDEX('Packet Builder'!$O$5:$O$34,$L14)-$M14-1)) -> 1 | D14: =IF($L14="","",IF($C14>$M14,"EOF",IFERROR(VALUE(TRIM(MID(SUBSTITUTE(INDEX('Packet Builder'!$P$5:$P$34,$L14),",",REPT(" ",LEN(INDEX('Packet Builder'!$P$5:$P$34,$L14)))),($C14-1)*LEN(INDEX('Packet Builder'!$P$5:$P$34,$L14))+1,LEN(INDEX('Packet Builder'!$P$5:$P$34,$L14))))),"ERR"))) -> 0 | E14: =IF($L14="","",IF($C14>$M14,"End of Frame Delimiter",IFERROR(INDEX(Fields!$B$5:$B$48,MATCH($D14,Fields!$A$5:$A$48,0)),"MISSING"))) -> Witness Status | F14: =IF($L14="","",SUMIF($L$5:L14,L14,$G$5:G14)-G14) -> 0 | G14: =IF($L14="","",IF($C14>$M14,Overview!$B$26,IFERROR(INDEX(Fields!$F$5:$F$48,MATCH($D14,Fields!$A$5:$A$48,0)),0))) -> 2 | H14: =IF($L14="","",F14+G14-1) -> 1 | I14: =IF($L14="","",IF($C14>$M14,IF(Overview!$B$26=1,"uint8","uint8["&Overview!$B$26&"]"),IFERROR(INDEX(Fields!$E$5:$E$48,MATCH($D14,Fields!$A$5:$A$48,0)),"MISSING"))) -> bitfield[16] | J14: =IF($L14="","",IF($C14>$M14,"Fixed end-of-frame delimiter, value "&Overview!$B$25&".",IFERROR(INDEX(Fields!$G$5:$G$48,MATCH($D14,Fields!$A$5:$A$48,0)),"MISSING"))) -> Byte 0 contains status flags; byte 1 is reserved. No numeric scale. | K14: =IF($L14="","",IF($C14>$M14,"n/a",IFERROR(INDEX(Fields!$H$5:$H$48,MATCH($D14,Fields!$A$5:$A$48,0)),"MISSING"))) -> IRIS_FIELD_WITNESS_STATUS_LENGTH | L14: =IF(ROWS($L$5:L14)>MAX('Packet Builder'!$O$5:$O$34),"",COUNTIF('Packet Builder'!$O$5:$O$34,"<"&ROWS($L$5:L14))+1) -> 2 | M14: =IF($L14="","",INDEX('Packet Builder'!$F$5:$F$34,$L14)) -> 17
A15: =IF($L15="","",INDEX('Packet Builder'!$A$5:$A$34,$L15)) -> 0x02 | B15: =IF($L15="","",INDEX('Packet Builder'!$B$5:$B$34,$L15)) -> State | C15: =IF($L15="","",ROWS($L$5:L15)-(INDEX('Packet Builder'!$O$5:$O$34,$L15)-$M15-1)) -> 2 | D15: =IF($L15="","",IF($C15>$M15,"EOF",IFERROR(VALUE(TRIM(MID(SUBSTITUTE(INDEX('Packet Builder'!$P$5:$P$34,$L15),",",REPT(" ",LEN(INDEX('Packet Builder'!$P$5:$P$34,$L15)))),($C15-1)*LEN(INDEX('Packet Builder'!$P$5:$P$34,$L15))+1,LEN(INDEX('Packet Builder'!$P$5:$P$34,$L15))))),"ERR"))) -> 1 | E15: =IF($L15="","",IF($C15>$M15,"End of Frame Delimiter",IFERROR(INDEX(Fields!$B$5:$B$48,MATCH($D15,Fields!$A$5:$A$48,0)),"MISSING"))) -> Witness Uptime | F15: =IF($L15="","",SUMIF($L$5:L15,L15,$G$5:G15)-G15) -> 2 | G15: =IF($L15="","",IF($C15>$M15,Overview!$B$26,IFERROR(INDEX(Fields!$F$5:$F$48,MATCH($D15,Fields!$A$5:$A$48,0)),0))) -> 4 | H15: =IF($L15="","",F15+G15-1) -> 5 | I15: =IF($L15="","",IF($C15>$M15,IF(Overview!$B$26=1,"uint8","uint8["&Overview!$B$26&"]"),IFERROR(INDEX(Fields!$E$5:$E$48,MATCH($D15,Fields!$A$5:$A$48,0)),"MISSING"))) -> uint32 | J15: =IF($L15="","",IF($C15>$M15,"Fixed end-of-frame delimiter, value "&Overview!$B$25&".",IFERROR(INDEX(Fields!$G$5:$G$48,MATCH($D15,Fields!$A$5:$A$48,0)),"MISSING"))) -> 1 ms/count; elapsed time since boot. | K15: =IF($L15="","",IF($C15>$M15,"n/a",IFERROR(INDEX(Fields!$H$5:$H$48,MATCH($D15,Fields!$A$5:$A$48,0)),"MISSING"))) -> IRIS_FIELD_WITNESS_UPTIME_LENGTH | L15: =IF(ROWS($L$5:L15)>MAX('Packet Builder'!$O$5:$O$34),"",COUNTIF('Packet Builder'!$O$5:$O$34,"<"&ROWS($L$5:L15))+1) -> 2 | M15: =IF($L15="","",INDEX('Packet Builder'!$F$5:$F$34,$L15)) -> 17
A16: =IF($L16="","",INDEX('Packet Builder'!$A$5:$A$34,$L16)) -> 0x02 | B16: =IF($L16="","",INDEX('Packet Builder'!$B$5:$B$34,$L16)) -> State | C16: =IF($L16="","",ROWS($L$5:L16)-(INDEX('Packet Builder'!$O$5:$O$34,$L16)-$M16-1)) -> 3 | D16: =IF($L16="","",IF($C16>$M16,"EOF",IFERROR(VALUE(TRIM(MID(SUBSTITUTE(INDEX('Packet Builder'!$P$5:$P$34,$L16),",",REPT(" ",LEN(INDEX('Packet Builder'!$P$5:$P$34,$L16)))),($C16-1)*LEN(INDEX('Packet Builder'!$P$5:$P$34,$L16))+1,LEN(INDEX('Packet Builder'!$P$5:$P$34,$L16))))),"ERR"))) -> 11 | E16: =IF($L16="","",IF($C16>$M16,"End of Frame Delimiter",IFERROR(INDEX(Fields!$B$5:$B$48,MATCH($D16,Fields!$A$5:$A$48,0)),"MISSING"))) -> Orientation Quaternion X | F16: =IF($L16="","",SUMIF($L$5:L16,L16,$G$5:G16)-G16) -> 6 | G16: =IF($L16="","",IF($C16>$M16,Overview!$B$26,IFERROR(INDEX(Fields!$F$5:$F$48,MATCH($D16,Fields!$A$5:$A$48,0)),0))) -> 4 | H16: =IF($L16="","",F16+G16-1) -> 9 | I16: =IF($L16="","",IF($C16>$M16,IF(Overview!$B$26=1,"uint8","uint8["&Overview!$B$26&"]"),IFERROR(INDEX(Fields!$E$5:$E$48,MATCH($D16,Fields!$A$5:$A$48,0)),"MISSING"))) -> IEEE-754 float32 | J16: =IF($L16="","",IF($C16>$M16,"Fixed end-of-frame delimiter, value "&Overview!$B$25&".",IFERROR(INDEX(Fields!$G$5:$G$48,MATCH($D16,Fields!$A$5:$A$48,0)),"MISSING"))) -> Unitless normalized quaternion component. | K16: =IF($L16="","",IF($C16>$M16,"n/a",IFERROR(INDEX(Fields!$H$5:$H$48,MATCH($D16,Fields!$A$5:$A$48,0)),"MISSING"))) -> IRIS_FIELD_ORIENTATION_QUAT_X_LENGTH | L16: =IF(ROWS($L$5:L16)>MAX('Packet Builder'!$O$5:$O$34),"",COUNTIF('Packet Builder'!$O$5:$O$34,"<"&ROWS($L$5:L16))+1) -> 2 | M16: =IF($L16="","",INDEX('Packet Builder'!$F$5:$F$34,$L16)) -> 17
... A404: =IF($L404="","",INDEX('Packet Builder'!$A$5:$A$34,$L404)) | B404: =IF($L404="","",INDEX('Packet Builder'!$B$5:$B$34,$L404)) | C404: =IF($L404="","",ROWS($L$5:L404)-(INDEX('Packet Builder'!$O$5:$O$34,$L404)-$M404-1)) | D404: =IF($L404="","",IF($C404>$M404,"EOF",IFERROR(VALUE(TRIM(MID(SUBSTITUTE(INDEX('Packet Builder'!$P$5:$P$34,$L404),",",REPT(" ",LEN(INDEX('Packet Builder'!$P$5:$P$34,$L404)))),($C404-1)*LEN(INDEX('Packet Builder'!$P$5:$P$34,$L404))+1,LEN(INDEX('Packet Builder'!$P$5:$P$34,$L404))))),"ERR"))) | E404: =IF($L404="","",IF($C404>$M404,"End of Frame Delimiter",IFERROR(INDEX(Fields!$B$5:$B$48,MATCH($D404,Fields!$A$5:$A$48,0)),"MISSING"))) | F404: =IF($L404="","",SUMIF($L$5:L404,L404,$G$5:G404)-G404) | G404: =IF($L404="","",IF($C404>$M404,Overview!$B$26,IFERROR(INDEX(Fields!$F$5:$F$48,MATCH($D404,Fields!$A$5:$A$48,0)),0))) | H404: =IF($L404="","",F404+G404-1) | I404: =IF($L404="","",IF($C404>$M404,IF(Overview!$B$26=1,"uint8","uint8["&Overview!$B$26&"]"),IFERROR(INDEX(Fields!$E$5:$E$48,MATCH($D404,Fields!$A$5:$A$48,0)),"MISSING"))) | J404: =IF($L404="","",IF($C404>$M404,"Fixed end-of-frame delimiter, value "&Overview!$B$25&".",IFERROR(INDEX(Fields!$G$5:$G$48,MATCH($D404,Fields!$A$5:$A$48,0)),"MISSING"))) | K404: =IF($L404="","",IF($C404>$M404,"n/a",IFERROR(INDEX(Fields!$H$5:$H$48,MATCH($D404,Fields!$A$5:$A$48,0)),"MISSING"))) | L404: =IF(ROWS($L$5:L404)>MAX('Packet Builder'!$O$5:$O$34),"",COUNTIF('Packet Builder'!$O$5:$O$34,"<"&ROWS($L$5:L404))+1) | M404: =IF($L404="","",INDEX('Packet Builder'!$F$5:$F$34,$L404))
